Workbook
Name Slicer_Sex: #N/A
Name Slicer_Pclass: #N/A
Name Slicer_Survived: #N/A
Name Slicer_Embarked: #N/A

Sheet Rawdata
A1: PassengerId | B1: Survived | C1: Pclass | D1: Name | E1: Sex | F1: Age | G1: SibSp | H1: Parch | I1: Ticket | J1: Fare | K1: Cabin | L1: Embarked
A2: 1 | B2: 0 | C2: 3 | D2: Braund, Mr. Owen Harris | E2: male | F2: 22 | G2: 1 | H2: 0 | I2: A/5 21171 | J2: 7.25 | L2: S
A3: 2 | B3: 1 | C3: 1 | D3: Cumings, Mrs. John Bradley (Florence Briggs Thayer) | E3: female | F3: 38 | G3: 1 | H3: 0 | I3: PC 17599 | J3: 71.2833 | K3: C85 | L3: C
A4: 3 | B4: 1 | C4: 3 | D4: Heikkinen, Miss. Laina | E4: female | F4: 26 | G4: 0 | H4: 0 | I4: STON/O2. 3101282 | J4: 7.925 | L4: S
A5: 4 | B5: 1 | C5: 1 | D5: Futrelle, Mrs. Jacques Heath (Lily May Peel) | E5: female | F5: 35 | G5: 1 | H5: 0 | I5: 113803 | J5: 53.1 | K5: C123 | L5: S
A6: 5 | B6: 0 | C6: 3 | D6: Allen, Mr. William Henry | E6: male | F6: 35 | G6: 0 | H6: 0 | I6: 373450 | J6: 8.05 | L6: S
A7: 6 | B7: 0 | C7: 3 | D7: Moran, Mr. James | E7: male | G7: 0 | H7: 0 | I7: 330877 | J7: 8.4583 | L7: Q
A8: 7 | B8: 0 | C8: 1 | D8: McCarthy, Mr. Timothy J | E8: male | F8: 54 | G8: 0 | H8: 0 | I8: 17463 | J8: 51.8625 | K8: E46 | L8: S
A9: 8 | B9: 0 | C9: 3 | D9: Palsson, Master. Gosta Leonard | E9: male | F9: 2 | G9: 3 | H9: 1 | I9: 349909 | J9: 21.075 | L9: S
A10: 9 | B10: 1 | C10: 3 | D10: Johnson, Mrs. Oscar W (Elisabeth Vilhelmina Berg) | E10: female | F10: 27 | G10: 0 | H10: 2 | I10: 347742 | J10: 11.1333 | L10: S
A11: 10 | B11: 1 | C11: 2 | D11: Nasser, Mrs. Nicholas (Adele Achem) | E11: female | F11: 14 | G11: 1 | H11: 0 | I11: 237736 | J11: 30.0708 | L11: C
A12: 11 | B12: 1 | C12: 3 | D12: Sandstrom, Miss. Marguerite Rut | E12: female | F12: 4 | G12: 1 | H12: 1 | I12: PP 9549 | J12: 16.7 | K12: G6 | L12: S
A13: 12 | B13: 1 | C13: 1 | D13: Bonnell, Miss. Elizabeth | E13: female | F13: 58 | G13: 0 | H13: 0 | I13: 113783 | J13: 26.55 | K13: C103 | L13: S
A14: 13 | B14: 0 | C14: 3 | D14: Saundercock, Mr. William Henry | E14: male | F14: 20 | G14: 0 | H14: 0 | I14: A/5. 2151 | J14: 8.05 | L14: S
A15: 14 | B15: 0 | C15: 3 | D15: Andersson, Mr. Anders Johan | E15: male | F15: 39 | G15: 1 | H15: 5 | I15: 347082 | J15: 31.275 | L15: S
A16: 15 | B16: 0 | C16: 3 | D16: Vestrom, Miss. Hulda Amanda Adolfina | E16: female | F16: 14 | G16: 0 | H16: 0 | I16: 350406 | J16: 7.8542 | L16: S
A17: 16 | B17: 1 | C17: 2 | D17: Hewlett, Mrs. (Mary D Kingcome) | E17: female | F17: 55 | G17: 0 | H17: 0 | I17: 248706 | J17: 16 | L17: S
A18: 17 | B18: 0 | C18: 3 | D18: Rice, Master. Eugene | E18: male | F18: 2 | G18: 4 | H18: 1 | I18: 382652 | J18: 29.125 | L18: Q
A19: 18 | B19: 1 | C19: 2 | D19: Williams, Mr. Charles Eugene | E19: male | G19: 0 | H19: 0 | I19: 244373 | J19: 13 | L19: S
A20: 19 | B20: 0 | C20: 3 | D20: Vander Planke, Mrs. Julius (Emelia Maria Vandemoortele) | E20: female | F20: 31 | G20: 1 | H20: 0 | I20: 345763 | J20: 18 | L20: S
A21: 20 | B21: 1 | C21: 3 | D21: Masselmani, Mrs. Fatima | E21: female | G21: 0 | H21: 0 | I21: 2649 | J21: 7.225 | L21: C
A22: 21 | B22: 0 | C22: 2 | D22: Fynney, Mr. Joseph J | E22: male | F22: 35 | G22: 0 | H22: 0 | I22: 239865 | J22: 26 | L22: S
A23: 22 | B23: 1 | C23: 2 | D23: Beesley, Mr. Lawrence | E23: male | F23: 34 | G23: 0 | H23: 0 | I23: 248698 | J23: 13 | K23: D56 | L23: S
A24: 23 | B24: 1 | C24: 3 | D24: McGowan, Miss. Anna "Annie" | E24: female | F24: 15 | G24: 0 | H24: 0 | I24: 330923 | J24: 8.0292 | L24: Q
A25: 24 | B25: 1 | C25: 1 | D25: Sloper, Mr. William Thompson | E25: male | F25: 28 | G25: 0 | H25: 0 | I25: 113788 | J25: 35.5 | K25: A6 | L25: S
A26: 25 | B26: 0 | C26: 3 | D26: Palsson, Miss. Torborg Danira | E26: female | F26: 8 | G26: 3 | H26: 1 | I26: 349909 | J26: 21.075 | L26: S
A27: 26 | B27: 1 | C27: 3 | D27: Asplund, Mrs. Carl Oscar (Selma Augusta Emilia Johansson) | E27: female | F27: 38 | G27: 1 | H27: 5 | I27: 347077 | J27: 31.3875 | L27: S
A28: 27 | B28: 0 | C28: 3 | D28: Emir, Mr. Farred Chehab | E28: male | G28: 0 | H28: 0 | I28: 2631 | J28: 7.225 | L28: C
A29: 28 | B29: 0 | C29: 1 | D29: Fortune, Mr. Charles Alexander | E29: male | F29: 19 | G29: 3 | H29: 2 | I29: 19950 | J29: 263 | K29: C23 C25 C27 | L29: S
A30: 29 | B30: 1 | C30: 3 | D30: O'Dwyer, Miss. Ellen "Nellie" | E30: female | G30: 0 | H30: 0 | I30: 330959 | J30: 7.8792 | L30: Q
A31: 30 | B31: 0 | C31: 3 | D31: Todoroff, Mr. Lalio | E31: male | G31: 0 | H31: 0 | I31: 349216 | J31: 7.8958 | L31: S
A32: 31 | B32: 0 | C32: 1 | D32: Uruchurtu, Don. Manuel E | E32: male | F32: 40 | G32: 0 | H32: 0 | I32: PC 17601 | J32: 27.7208 | L32: C
A33: 32 | B33: 1 | C33: 1 | D33: Spencer, Mrs. William Augustus (Marie Eugenie) | E33: female | G33: 1 | H33: 0 | I33: PC 17569 | J33: 146.5208 | K33: B78 | L33: C
A34: 33 | B34: 1 | C34: 3 | D34: Glynn, Miss. Mary Agatha | E34: female | G34: 0 | H34: 0 | I34: 335677 | J34: 7.75 | L34: Q
A35: 34 | B35: 0 | C35: 2 | D35: Wheadon, Mr. Edward H | E35: male | F35: 66 | G35: 0 | H35: 0 | I35: C.A. 24579 | J35: 10.5 | L35: S
A36: 35 | B36: 0 | C36: 1 | D36: Meyer, Mr. Edgar Joseph | E36: male | F36: 28 | G36: 1 | H36: 0 | I36: PC 17604 | J36: 82.1708 | L36: C
A37: 36 | B37: 0 | C37: 1 | D37: Holverson, Mr. Alexander Oskar | E37: male | F37: 42 | G37: 1 | H37: 0 | I37: 113789 | J37: 52 | L37: S
A38: 37 | B38: 1 | C38: 3 | D38: Mamee, Mr. Hanna | E38: male | G38: 0 | H38: 0 | I38: 2677 | J38: 7.2292 | L38: C
A39: 38 | B39: 0 | C39: 3 | D39: Cann, Mr. Ernest Charles | E39: male | F39: 21 | G39: 0 | H39: 0 | I39: A./5. 2152 | J39: 8.05 | L39: S
A40: 39 | B40: 0 | C40: 3 | D40: Vander Planke, Miss. Augusta Maria | E40: female | F40: 18 | G40: 2 | H40: 0 | I40: 345764 | J40: 18 | L40: S
...

Sheet Titanic.csv
A1: PassengerId | B1: Survived | C1: Pclass | D1: Name | E1: Sex | F1: Age | G1: SibSp | H1: Parch | I1: Ticket | J1: Fare | K1: Cabin | L1: Embarked | M1: Age_clean
A2: 1 | B2: 0 | C2: 3 | D2: Braund, Mr. Owen Harris | E2: male | F2: 22 | G2: 1 | H2: 0 | I2: A/5 21171 | J2: 7.25 | L2: S | M2: =IF(F2="",AVERAGE($F$2:$F$892),F2) -> 22
A3: 2 | B3: 1 | C3: 1 | D3: Cumings, Mrs. John Bradley (Florence Briggs Thayer) | E3: female | F3: 38 | G3: 1 | H3: 0 | I3: PC 17599 | J3: 71.2833 | K3: C85 | L3: C | M3: =IF(F3="",AVERAGE($F$2:$F$892),F3) -> 38
A4: 3 | B4: 1 | C4: 3 | D4: Heikkinen, Miss. Laina | E4: female | F4: 26 | G4: 0 | H4: 0 | I4: STON/O2. 3101282 | J4: 7.925 | L4: S | M4: =IF(F4="",AVERAGE($F$2:$F$892),F4) -> 26
A5: 4 | B5: 1 | C5: 1 | D5: Futrelle, Mrs. Jacques Heath (Lily May Peel) | E5: female | F5: 35 | G5: 1 | H5: 0 | I5: 113803 | J5: 53.1 | K5: C123 | L5: S | M5: =IF(F5="",AVERAGE($F$2:$F$892),F5) -> 35
A6: 5 | B6: 0 | C6: 3 | D6: Allen, Mr. William Henry | E6: male | F6: 35 | G6: 0 | H6: 0 | I6: 373450 | J6: 8.05 | L6: S | M6: =IF(F6="",AVERAGE($F$2:$F$892),F6) -> 35 | Z6: We
A7: 6 | B7: 0 | C7: 3 | D7: Moran, Mr. James | E7: male | G7: 0 | H7: 0 | I7: 330877 | J7: 8.4583 | L7: Q | M7: =IF(F7="",AVERAGE($F$2:$F$892),F7) -> 29.699118
A8: 7 | B8: 0 | C8: 1 | D8: McCarthy, Mr. Timothy J | E8: male | F8: 54 | G8: 0 | H8: 0 | I8: 17463 | J8: 51.8625 | K8: E46 | L8: S | M8: =IF(F8="",AVERAGE($F$2:$F$892),F8) -> 54
A9: 8 | B9: 0 | C9: 3 | D9: Palsson, Master. Gosta Leonard | E9: male | F9: 2 | G9: 3 | H9: 1 | I9: 349909 | J9: 21.075 | L9: S | M9: =IF(F9="",AVERAGE($F$2:$F$892),F9) -> 2
A10: 9 | B10: 1 | C10: 3 | D10: Johnson, Mrs. Oscar W (Elisabeth Vilhelmina Berg) | E10: female | F10: 27 | G10: 0 | H10: 2 | I10: 347742 | J10: 11.1333 | L10: S | M10: =IF(F10="",AVERAGE($F$2:$F$892),F10) -> 27
A11: 10 | B11: 1 | C11: 2 | D11: Nasser, Mrs. Nicholas (Adele Achem) | E11: female | F11: 14 | G11: 1 | H11: 0 | I11: 237736 | J11: 30.0708 | L11: C | M11: =IF(F11="",AVERAGE($F$2:$F$892),F11) -> 14
A12: 11 | B12: 1 | C12: 3 | D12: Sandstrom, Miss. Marguerite Rut | E12: female | F12: 4 | G12: 1 | H12: 1 | I12: PP 9549 | J12: 16.7 | K12: G6 | L12: S | M12: =IF(F12="",AVERAGE($F$2:$F$892),F12) -> 4
A13: 12 | B13: 1 | C13: 1 | D13: Bonnell, Miss. Elizabeth | E13: female | F13: 58 | G13: 0 | H13: 0 | I13: 113783 | J13: 26.55 | K13: C103 | L13: S | M13: =IF(F13="",AVERAGE($F$2:$F$892),F13) -> 58
A14: 13 | B14: 0 | C14: 3 | D14: Saundercock, Mr. William Henry | E14: male | F14: 20 | G14: 0 | H14: 0 | I14: A/5. 2151 | J14: 8.05 | L14: S | M14: =IF(F14="",AVERAGE($F$2:$F$892),F14) -> 20
A15: 14 | B15: 0 | C15: 3 | D15: Andersson, Mr. Anders Johan | E15: male | F15: 39 | G15: 1 | H15: 5 | I15: 347082 | J15: 31.275 | L15: S | M15: =IF(F15="",AVERAGE($F$2:$F$892),F15) -> 39
A16: 15 | B16: 0 | C16: 3 | D16: Vestrom, Miss. Hulda Amanda Adolfina | E16: female | F16: 14 | G16: 0 | H16: 0 | I16: 350406 | J16: 7.8542 | L16: S | M16: =IF(F16="",AVERAGE($F$2:$F$892),F16) -> 14
A17: 16 | B17: 1 | C17: 2 | D17: Hewlett, Mrs. (Mary D Kingcome) | E17: female | F17: 55 | G17: 0 | H17: 0 | I17: 248706 | J17: 16 | L17: S | M17: =IF(F17="",AVERAGE($F$2:$F$892),F17) -> 55
A18: 17 | B18: 0 | C18: 3 | D18: Rice, Master. Eugene | E18: male | F18: 2 | G18: 4 | H18: 1 | I18: 382652 | J18: 29.125 | L18: Q | M18: =IF(F18="",AVERAGE($F$2:$F$892),F18) -> 2
A19: 18 | B19: 1 | C19: 2 | D19: Williams, Mr. Charles Eugene | E19: male | G19: 0 | H19: 0 | I19: 244373 | J19: 13 | L19: S | M19: =IF(F19="",AVERAGE($F$2:$F$892),F19) -> 29.699118
A20: 19 | B20: 0 | C20: 3 | D20: Vander Planke, Mrs. Julius (Emelia Maria Vandemoortele) | E20: female | F20: 31 | G20: 1 | H20: 0 | I20: 345763 | J20: 18 | L20: S | M20: =IF(F20="",AVERAGE($F$2:$F$892),F20) -> 31
A21: 20 | B21: 1 | C21: 3 | D21: Masselmani, Mrs. Fatima | E21: female | G21: 0 | H21: 0 | I21: 2649 | J21: 7.225 | L21: C | M21: =IF(F21="",AVERAGE($F$2:$F$892),F21) -> 29.699118
A22: 21 | B22: 0 | C22: 2 | D22: Fynney, Mr. Joseph J | E22: male | F22: 35 | G22: 0 | H22: 0 | I22: 239865 | J22: 26 | L22: S | M22: =IF(F22="",AVERAGE($F$2:$F$892),F22) -> 35
A23: 22 | B23: 1 | C23: 2 | D23: Beesley, Mr. Lawrence | E23: male | F23: 34 | G23: 0 | H23: 0 | I23: 248698 | J23: 13 | K23: D56 | L23: S | M23: =IF(F23="",AVERAGE($F$2:$F$892),F23) -> 34
A24: 23 | B24: 1 | C24: 3 | D24: McGowan, Miss. Anna "Annie" | E24: female | F24: 15 | G24: 0 | H24: 0 | I24: 330923 | J24: 8.0292 | L24: Q | M24: =IF(F24="",AVERAGE($F$2:$F$892),F24) -> 15
A25: 24 | B25: 1 | C25: 1 | D25: Sloper, Mr. William Thompson | E25: male | F25: 28 | G25: 0 | H25: 0 | I25: 113788 | J25: 35.5 | K25: A6 | L25: S | M25: =IF(F25="",AVERAGE($F$2:$F$892),F25) -> 28
A26: 25 | B26: 0 | C26: 3 | D26: Palsson, Miss. Torborg Danira | E26: female | F26: 8 | G26: 3 | H26: 1 | I26: 349909 | J26: 21.075 | L26: S | M26: =IF(F26="",AVERAGE($F$2:$F$892),F26) -> 8
A27: 26 | B27: 1 | C27: 3 | D27: Asplund, Mrs. Carl Oscar (Selma Augusta Emilia Johansson) | E27: female | F27: 38 | G27: 1 | H27: 5 | I27: 347077 | J27: 31.3875 | L27: S | M27: =IF(F27="",AVERAGE($F$2:$F$892),F27) -> 38
A28: 27 | B28: 0 | C28: 3 | D28: Emir, Mr. Farred Chehab | E28: male | G28: 0 | H28: 0 | I28: 2631 | J28: 7.225 | L28: C | M28: =IF(F28="",AVERAGE($F$2:$F$892),F28) -> 29.699118
A29: 28 | B29: 0 | C29: 1 | D29: Fortune, Mr. Charles Alexander | E29: male | F29: 19 | G29: 3 | H29: 2 | I29: 19950 | J29: 263 | K29: C23 C25 C27 | L29: S | M29: =IF(F29="",AVERAGE($F$2:$F$892),F29) -> 19
A30: 29 | B30: 1 | C30: 3 | D30: O'Dwyer, Miss. Ellen "Nellie" | E30: female | G30: 0 | H30: 0 | I30: 330959 | J30: 7.8792 | L30: Q | M30: =IF(F30="",AVERAGE($F$2:$F$892),F30) -> 29.699118
A31: 30 | B31: 0 | C31: 3 | D31: Todoroff, Mr. Lalio | E31: male | G31: 0 | H31: 0 | I31: 349216 | J31: 7.8958 | L31: S | M31: =IF(F31="",AVERAGE($F$2:$F$892),F31) -> 29.699118
A32: 31 | B32: 0 | C32: 1 | D32: Uruchurtu, Don. Manuel E | E32: male | F32: 40 | G32: 0 | H32: 0 | I32: PC 17601 | J32: 27.7208 | L32: C | M32: =IF(F32="",AVERAGE($F$2:$F$892),F32) -> 40
A33: 32 | B33: 1 | C33: 1 | D33: Spencer, Mrs. William Augustus (Marie Eugenie) | E33: female | G33: 1 | H33: 0 | I33: PC 17569 | J33: 146.5208 | K33: B78 | L33: C | M33: =IF(F33="",AVERAGE($F$2:$F$892),F33) -> 29.699118
A34: 33 | B34: 1 | C34: 3 | D34: Glynn, Miss. Mary Agatha | E34: female | G34: 0 | H34: 0 | I34: 335677 | J34: 7.75 | L34: Q | M34: =IF(F34="",AVERAGE($F$2:$F$892),F34) -> 29.699118
A35: 34 | B35: 0 | C35: 2 | D35: Wheadon, Mr. Edward H | E35: male | F35: 66 | G35: 0 | H35: 0 | I35: C.A. 24579 | J35: 10.5 | L35: S | M35: =IF(F35="",AVERAGE($F$2:$F$892),F35) -> 66
A36: 35 | B36: 0 | C36: 1 | D36: Meyer, Mr. Edgar Joseph | E36: male | F36: 28 | G36: 1 | H36: 0 | I36: PC 17604 | J36: 82.1708 | L36: C | M36: =IF(F36="",AVERAGE($F$2:$F$892),F36) -> 28
A37: 36 | B37: 0 | C37: 1 | D37: Holverson, Mr. Alexander Oskar | E37: male | F37: 42 | G37: 1 | H37: 0 | I37: 113789 | J37: 52 | L37: S | M37: =IF(F37="",AVERAGE($F$2:$F$892),F37) -> 42
A38: 37 | B38: 1 | C38: 3 | D38: Mamee, Mr. Hanna | E38: male | G38: 0 | H38: 0 | I38: 2677 | J38: 7.2292 | L38: C | M38: =IF(F38="",AVERAGE($F$2:$F$892),F38) -> 29.699118
A39: 38 | B39: 0 | C39: 3 | D39: Cann, Mr. Ernest Charles | E39: male | F39: 21 | G39: 0 | H39: 0 | I39: A./5. 2152 | J39: 8.05 | L39: S | M39: =IF(F39="",AVERAGE($F$2:$F$892),F39) -> 21
A40: 39 | B40: 0 | C40: 3 | D40: Vander Planke, Miss. Augusta Maria | E40: female | F40: 18 | G40: 2 | H40: 0 | I40: 345764 | J40: 18 | L40: S | M40: =IF(F40="",AVERAGE($F$2:$F$892),F40) -> 18
...

Sheet Analysis
A1: AGGREGATE FUNCTIONS | C1: LOGICAL FUNCTIONS | E1: LOOKUP FUNCTIONS
A3: TOTAL COUNT OF THE PASSENGERS | C3: TO CHECK THE SURVIVAL STATUS | E3: GET NAME OF THE PASSENGER BY ID(XLOOKUP)
A4: =COUNT(Titanic.csv!A:A) -> 891 | C4: =IF(Titanic.csv!B2,"Survived","Not survived") -> Not survived | E4: 345 | I4: Pclass | J4: Class Name
C5: =IF(Titanic.csv!B3,"Survived","Not survived") -> Survived | E5: =_xlfn.XLOOKUP(E4,Titanic.csv!A:A,Titanic.csv!D:D,"NOT FOUND") -> Fox, Mr. Stanley Hubert | I5: 1 | J5: 1st Class
A6: MALE PROPORTION | I6: 2 | J6: 2nd Class
A7: =C15/A4 -> 0.64758698 | C7: CHECK MISSING AGE OR CABIN | E7: PASSENGER CLASS (VLOOKUP) | I7: 3 | J7: 3rd Class
C8: =IF(OR(Titanic.csv!F2="",Titanic.csv!K2=""),"Missing Information","Complete") -> Missing Information | E8: =VLOOKUP(Titanic.csv!C2,$I$5:$J$7,2,FALSE) -> 3rd Class
A9: FEMALE PROPORTION | C9: =IF(OR(Titanic.csv!F3="",Titanic.csv!K3=""),"Missing Information","Complete") -> Complete | E9: =VLOOKUP(Titanic.csv!C3,$I$5:$J$7,2,FALSE) -> 1st Class
A10: =C18/A4 -> 0.35241302 | I10: 0 | J10: 1
C11: PASSENGER CLASS CATEGORY | E11: SURVIVAL STATUS (HLOOKUP) | I11: Not Survived | J11: Survived
A12: AVERAGE SURVIVAL RATE | C12: {=_xlfn.IFS(Titanic.csv!C2=1,"1st class",Titanic.csv!C2=2,"2nd class",Titanic.csv!C2=3,"3rd class")} -> 3rd class | E12: =HLOOKUP(Titanic.csv!B2,$I$10:$J$11,2,FALSE) -> Not Survived
A13: =AVERAGE(Titanic.csv!B:B) -> 0.38383838 | E13: =HLOOKUP(Titanic.csv!B3,$I$10:$J$11,2,FALSE) -> Survived
C14: TOTAL MALE PASSENGERS
A15: SUM OF FARE | C15: =COUNTIF(Titanic.csv!E:E,"MALE") -> 577 | E15: TO FIND ID BY NAME(INDEX & MATCH)
A16: =SUM(Titanic.csv!J:J) -> 28693.949 | E16: Najib, Miss. Adele Kiamie "Jane"
C17: TOTAL FEMALE PASSENGERS | E17: {=INDEX(Titanic.csv!A:A,MATCH(E16,Titanic.csv!D:D,0))} -> 876
A18: AVERAGE TICKET FARE | C18: =COUNTIF(Titanic.csv!E:E,"FEMALE") -> 314
A19: =AVERAGE(Titanic.csv!J:J) -> 32.204208
C20: SURVIVORS
A21: HIGHEST TICKET FARE | C21: =COUNTIF(Titanic.csv!B:B,1) -> 342
A22: =MAX(Titanic.csv!J:J) -> 512.3292
A24: AVERAGE AGE
A25: =AVERAGE(Titanic.csv!F:F) -> 29.699118
B170: Survival analysis
B171: Total passengers | C171: =COUNTA(Titanic.csv!A2:A892) -> 891
B172: Survivors | C172: =COUNTIF(Titanic.csv!B2:B892,1) -> 342
B173: Survival rate | C173: =C172/C171 -> 0.38383838
B175: Average age | C175: =AVERAGE(Titanic.csv!F2:F892) -> 29.699118
B177: Male passengers | C177: =COUNTIF(Titanic.csv!E2:E892,"male") -> 577
B178: Female passengers | C178: =COUNTIF(Titanic.csv!E2:E892,"female") -> 314
B179: Male proportion | C179: =C177/C171 -> 0.64758698
B180: Female proportion | C180: =C178/C171 -> 0.35241302

Sheet PivotTable
A2: SURVIVAL BY GENDER
A3: Count of PassengerId | B3: Survived
A4: Sex | B4: 0 | C4: 1 | D4: Grand Total
A5: female | B5: 81 | C5: 233 | D5: 314
A6: male | B6: 468 | C6: 109 | D6: 577
A7: Grand Total | B7: 549 | C7: 342 | D7: 891
A22: SURVIVAL BY PASSENGER CLASS
A23: Count of PassengerId | B23: Survived
A24: Pclass | B24: 0 | C24: 1 | D24: Grand Total
A25: 1 | B25: 80 | C25: 136 | D25: 216
A26: 2 | B26: 97 | C26: 87 | D26: 184
A27: 3 | B27: 372 | C27: 119 | D27: 491
A28: Grand Total | B28: 549 | C28: 342 | D28: 891
A42: SURVIVAL BY EMBARKED PORT
A43: Count of PassengerId | B43: Survived
A44: Embarked | B44: 0 | C44: 1 | D44: Grand Total
A45: C | B45: 75 | C45: 93 | D45: 168
A46: Q | B46: 47 | C46: 30 | D46: 77
A47: S | B47: 427 | C47: 217 | D47: 644
A48: (blank) | C48: 2 | D48: 2
A49: Grand Total | B49: 549 | C49: 342 | D49: 891
A61: AGE GROUP VS SURVIVAL
A62: Count of PassengerId | B62: Sex
A63: Pclass | B63: female | C63: male | D63: Grand Total
A64: 1 | B64: 94 | C64: 122 | D64: 216
A65: 2 | B65: 76 | C65: 108 | D65: 184
A66: 3 | B66: 144 | C66: 347 | D66: 491
A67: Grand Total | B67: 314 | C67: 577 | D67: 891
A79: SURVIVAL BY SEX & PASSENGER CLASS
A80: Count of PassengerId | C80: Survived
A81: Pclass | B81: Sex | C81: 0 | D81: 1 | E81: Grand Total
A82: 1 | C82: 80 | D82: 136 | E82: 216
B83: female | C83: 3 | D83: 91 | E83: 94
B84: male | C84: 77 | D84: 45 | E84: 122
A85: 2 | C85: 97 | D85: 87 | E85: 184
B86: female | C86: 6 | D86: 70 | E86: 76
B87: male | C87: 91 | D87: 17 | E87: 108
A88: 3 | C88: 372 | D88: 119 | E88: 491
B89: female | C89: 72 | D89: 72 | E89: 144
B90: male | C90: 300 | D90: 47 | E90: 347
...

Sheet Dashboard
D1: TITANIC DATA ANALYSIS DASHBOARD
D6: TOTAL PASSENGERS | F6: SURVIVORS | H6: SURVIVAL RATE | J6: MALE PASSENGERS | L6: FEMALE PASSENGERS | N6: PERISHED
D7: 891 | F7: 342 | H7: 0.3838 | J7: 577 | L7: 314 | N7: 549
D43: KEY INSIGHTS:
D45: Total passengers: 891
D46: Total survivors: 342
D47: Total perished: 549
D48: Overall survival rate: 38.38%
D49: Female passengers had a higher survival rate than male passengers
D50: First-class passengers had better survival outcome than third-class passengers
D51: First-class females had the highest survival rate, while third-class males had one of the lowest
